<mujoco model="sigmaban">
	<compiler angle="radian"/>
	<worldbody>
		<body name="torso">
			<freejoint name="root"/>
			<geom size="0.0725 0.057796 0.003" pos="0.0603892 1.47174e-07 0.0680823" quat="0.5 -0.5 0.5 -0.5" type="box"/>
			<geom size="0.0201 0.03055 0.0205" pos="0.0209392 0.0464001 0.022" quat="0 0.707107 -0.707107 0" type="box"/>
			<geom size="0.0201 0.03055 0.0205" pos="0.0209392 -0.0463999 0.022" quat="0 0.707107 -0.707107 0" type="box"/>
			<geom size="0.0201 0.03055 0.0205" pos="0.0158392 1.47174e-07 0.157" quat="0.707107 0 0 -0.707107" type="box"/>
			<geom size="0.0725 0.057796 0.003" pos="-0.0596108 1.47174e-07 0.0719177" quat="0.5 0.5 0.5 0.5" type="box"/>
			<geom size="0.0201 0.03055 0.0205" pos="0.0108392 0.0560001 0.164" quat="0.5 -0.5 -0.5 -0.5" type="box"/>
			<geom size="0.0201 0.03055 0.0205" pos="0.0108392 -0.0559999 0.164" quat="0.5 0.5 0.5 -0.5" type="box"/>
			<body name="u_neck" pos="0.0333892 1.47174e-07 0.1805" quat="0.707107 0 0 -0.707107">
				<inertial pos="0 0 0.0206334" quat="0.707107 0 0 0.707107" mass="0.0544799" diaginertia="5.16952e-05 3.05787e-05 2.98525e-05"/>
				<joint name="head_yaw" pos="0 0 0" axis="0 0 1" range="-2.0944 2.0944"/>
				<geom size="0.015 0.032901 0.0015" pos="0.025 0 0.032901" quat="0.5 0.5 -0.5 -0.5" type="box"/>
				<geom size="0.015 0.032901 0.0015" pos="-0.025 0 0.032901" quat="0.5 0.5 0.5 0.5" type="box"/>
				<geom size="0.0245 0.015 0.003125" pos="0 0 0.003125" quat="0 1 0 0" type="box"/>
				<body name="head_2023__field_of_view_false" pos="-0.0235 0 0.058302" quat="0.5 0.5 -0.5 -0.5">
					<inertial pos="-0.000139838 0.00397747 -0.0233757" quat="0.713826 0.697167 -0.0325639 0.05787" mass="0.257265" diaginertia="0.000251953 0.000245992 0.000105535"/>
					<joint name="head_pitch" pos="0 0 0" axis="0 0 1" range="-0.785398 1.5708"/>
					<geom size="0.0235 0.0015" pos="-0.0238 0.0365 -0.005" quat="0 0 1 0" type="cylinder"/>
					<geom size="0.0308 0.0235 0.0015" pos="0.01 0.0365 -0.005" quat="0 0 1 0" type="box"/>
					<geom size="0.0235 0.0015" pos="-0.0238 0.0365 -0.049" quat="0 0 1 0" type="cylinder"/>
					<geom size="0.0308 0.0235 0.0015" pos="0.01 0.0365 -0.049" quat="0 0 1 0" type="box"/>
					<geom size="0.0201 0.03055 0.0205" pos="0 -0.01755 -0.0235" type="box"/>
				</body>
			</body>
			<body name="u_shoulder_2023" pos="0.0283892 0.0795001 0.164" quat="0.707107 -0.707107 0 0">
				<inertial pos="0 0.00364642 0.0214003" quat="0.534183 0.463302 0.534183 0.463302" mass="0.0751043" diaginertia="5.70899e-05 4.53448e-05 3.35766e-05"/>
				<joint name="left_shoulder_pitch" pos="0 0 0" axis="0 0 1" range="-2.18166 2.18166"/>
				<geom size="0.0245 0.015 0.003125" pos="0 0 0.007125" quat="0 -1 0 0" type="box"/>
				<body name="left_humerus" pos="0.0235 0.03 0.03" quat="0.092296 -0.701057 0.092296 -0.701057">
					<inertial pos="0.000340637 -0.0522685 -0.0268822" quat="0.6755 0.737155 -0.00965607 0.0144769" mass="0.243502" diaginertia="0.0007708 0.000757172 7.90289e-05"/>
					<joint name="left_shoulder_roll" pos="0 0 0" axis="0 0 1" range="-0.261799 1.309"/>
					<geom size="0.0201 0.03055 0.0205" pos="0 -0.01755 -0.0235" type="box"/>
					<geom size="0.0525 0.015 0.0015" pos="0 -0.1045 -0.04" quat="0 0.707107 -0.707107 0" type="box"/>
					<body name="radius_v2" pos="0.0235 -0.142 -0.0025" quat="0.707107 0 0.707107 0">
						<inertial pos="7.98171e-05 -0.0556905 -0.0234333" quat="0.516125 0.5144 -0.483923 0.484589" mass="0.256846" diaginertia="0.000947096 0.000937203 0.000130591"/>
						<joint name="left_elbow" pos="0 0 0" axis="0 0 1" range="-2.79253 0.261799"/>
						<geom size="0.04 0.0015" pos="0 -0.1496 -0.042" quat="0.707107 0 0 -0.707107" type="cylinder"/>
						<geom size="0.0497756 0.0206 0.0015" pos="0 -0.0649756 -0.042" quat="0.707107 0 0 -0.707107" type="box"/>
						<geom size="0.0201 0.03055 0.0205" pos="0 -0.01755 -0.0235" quat="1 0 0 0" type="box"/>
						<geom size="0.04 0.0015" pos="0 -0.1496 -0.005" quat="0.707107 0 0 -0.707107" type="cylinder"/>
						<geom size="0.0497756 0.0206 0.0015" pos="0 -0.0649756 -0.005" quat="0.707107 0 0 -0.707107" type="box"/>
					</body>
				</body>
			</body>
			<body name="u_shoulder_2023_2" pos="0.0283892 -0.0794999 0.164" quat="0 0 -0.707107 -0.707107">
				<inertial pos="0 -0.00364642 -0.0214003" quat="0.534183 0.463302 0.534183 0.463302" mass="0.0751043" diaginertia="5.70899e-05 4.53448e-05 3.35766e-05"/>
				<joint name="right_shoulder_pitch" pos="0 0 0" axis="0 0 1" range="-2.18166 2.18166"/>
				<geom size="0.0245 0.015 0.003125" pos="0 0 -0.007125" type="box"/>
				<body name="right_humerus" pos="-0.0235 -0.03 -0.03" quat="0.701057 0.092296 -0.701057 -0.092296">
					<inertial pos="-0.000172255 -0.0522685 -0.0268669" quat="0.675487 0.736848 -0.0236007 0.014685" mass="0.243502" diaginertia="0.000770875 0.000757172 7.90454e-05"/>
					<joint name="right_shoulder_roll" pos="0 0 0" axis="0 0 1" range="-1.309 0.261799"/>
					<geom size="0.0525 0.015 0.0015" pos="0 -0.1045 -0.04" quat="0 -0.707107 0.707107 0" type="box"/>
					<geom size="0.0201 0.03055 0.0205" pos="0 -0.01755 -0.0235" type="box"/>
					<body name="radius_v2_2" pos="-0.0235 -0.142 -0.0025" quat="0 -0.707107 0 -0.707107">
						<inertial pos="7.98171e-05 0.0556905 0.0234333" quat="0.484589 0.483923 -0.5144 0.516125" mass="0.256846" diaginertia="0.000947096 0.000937203 0.000130591"/>
						<joint name="right_elbow" pos="0 0 0" axis="0 0 1" range="-2.79253 0.261799"/>
						<geom size="0.04 0.0015" pos="0 0.1496 0.005" quat="0 0.707107 0.707107 0" type="cylinder"/>
						<geom size="0.0497756 0.0206 0.0015" pos="0 0.0649756 0.005" quat="0 0.707107 0.707107 0" type="box"/>
						<geom size="0.04 0.0015" pos="0 0.1496 0.042" quat="0 0.707107 0.707107 0" type="cylinder"/>
						<geom size="0.0497756 0.0206 0.0015" pos="0 0.0649756 0.042" quat="0 0.707107 0.707107 0" type="box"/>
						<geom size="0.0201 0.03055 0.0205" pos="0 0.01755 0.0235" quat="0 1 0 0" type="box"/>
					</body>
				</body>
			</body>
			<body name="u_block_2023" pos="0.0033892 0.0464001 -0.021" quat="0 0 0 -1">
				<inertial pos="-0.00509532 -8.44195e-07 -0.00985131" quat="0.531959 0.465906 0.466024 0.531765" mass="0.0630136" diaginertia="4.24266e-05 3.5526e-05 2.00009e-05"/>
				<joint name="left_hip_yaw" pos="0 0 0" axis="0 0 1" range="-1.0472 1.0472"/>
				<geom size="0.01875 0.02375 0.0015" pos="-0.03144 0 -0.02375" quat="0.5 0.5 0.5 0.5" type="box"/>
				<geom size="0.01875 0.02375 0.0015" pos="0.0219 0 -0.02375" quat="0.5 -0.5 0.5 -0.5" type="box"/>
				<body name="mx106_block_hip__list_0bj1pweadmbeeq_hip" pos="0.0234 0 -0.04" quat="0.5 0.5 -0.5 -0.5">
					<inertial pos="-0.000525167 -0.0153964 0.00382779" quat="0.996695 -0.0796662 -0.00761504 0.0139099" mass="0.397097" diaginertia="0.000428697 0.000375755 0.000176713"/>
					<joint name="left_hip_roll" pos="0 0 0" axis="0 0 1" range="-0.523599 0.610865"/>
					<geom size="0.0201 0.03255 0.023" pos="0 -0.01805 -0.026" type="box"/>
					<geom size="0.0201 0.03255 0.023" pos="0 -0.01805 0.0234" quat="0.707107 0 0.707107 0" type="box"/>
					<body name="left_knee_2023" pos="0.0295 0 0.0234" quat="0 0.707107 0 0.707107">
						<inertial pos="-3.04946e-05 0.100616 -0.0296228" quat="0.722599 0.691267 -0.000117213 -0.000114115" mass="0.268473" diaginertia="0.000539256 0.000462483 0.000122223"/>
						<joint name="left_hip_pitch" pos="0 0 0" axis="0 0 1" range="-1.5708 1.5708"/>
						<geom size="0.0201 0.03255 0.023" pos="0 0.12195 -0.0295" quat="1 0 0 0" type="box"/>
						<geom size="0.015 0.04825 0.0015" pos="0 0.03725 -0.057" quat="0 1 0 0" type="box"/>
						<geom size="0.015 0.04825 0.0015" pos="0 0.03725 0.0015" type="box"/>
						<body name="tibia_2023" pos="0 0.14 -0.001" quat="1 0 0 0">
							<inertial pos="-0.00296199 0.0631405 -0.0268398" quat="0.706918 0.707174 -0.00934954 -0.00915237" mass="0.113077" diaginertia="0.000351979 0.00027164 0.000103748"/>
							<joint name="left_knee" pos="0 0 0" axis="0 0 1" range="0 3.14159"/>
							<geom size="0.0202131 0.0850495 0.0015" pos="-0.0062131 0.068951 0.0015" quat="0 0 -1 0" type="box"/>
							<geom size="0.0202131 0.0850495 0.0015" pos="-0.0062131 0.068951 -0.05594" quat="0 0 -1 0" type="box"/>
							<body name="mx106_block_mir_ankle" pos="0 0.14 0" quat="0 0 0 1">
								<inertial pos="0.0195695 0.0153964 -0.0290274" quat="-0.0662501 0.699432 0.0464073 0.710107" mass="0.397097" diaginertia="0.000428738 0.000375795 0.000176713"/>
								<joint name="left_ankle_pitch" pos="0 0 0" axis="0 0 1" range="-1.5708 1.5708"/>
								<geom size="0.0201 0.03255 0.023" pos="0 0.01805 -0.0285" quat="0 0 0 1" type="box"/>
								<geom size="0.0201 0.03255 0.023" pos="0.0494 0.01805 -0.0285" quat="0 -0.707107 0 0.707107" type="box"/>
								<body name="left_foot___list_t0v6opd9rekumc_default" pos="0.0234 0 -0.0285" quat="0.707107 0 -0.707107 0">
									<inertial pos="0.00454445 -0.0365542 0.0466461" quat="0.711591 -0.00420022 0.0112517 0.702491" mass="0.281856" diaginertia="0.000922792 0.000718237 0.000264953"/>
									<joint name="left_ankle_roll" pos="0 0 0" axis="0 0 1" range="-0.785398 0.785398"/>
									<geom size="0.008 0.008" pos="0.0435 -0.0535 -0.03213" quat="0.707107 0.707107 0 0" type="cylinder"/>
									<geom size="0.02617 0.015 0.003125" pos="0 -0.036875 0.02817" quat="0.5 0.5 0.5 -0.5" type="box"/>
									<geom size="0.008 0.008" pos="-0.0325 -0.0535 -0.03213" quat="0.707107 0.707107 0 0" type="cylinder"/>
									<geom size="0.008 0.008" pos="0.0435 -0.0535 0.10947" quat="0 0 -0.707107 0.707107" type="cylinder"/>
									<geom size="0.046 0.0788 0.0015" pos="0.0055 -0.0415 0.03867" quat="0.707107 -0.707107 0 0" type="box"/>
									<geom size="0.008 0.008" pos="-0.0325 -0.0535 0.10947" quat="0 0 -0.707107 0.707107" type="cylinder"/>
								</body>
							</body>
						</body>
					</body>
				</body>
			</body>
			<body name="u_block_2023_2" pos="0.0033892 -0.0463999 -0.021" quat="0 0 0 -1">
				<inertial pos="-0.00509532 -8.44195e-07 -0.00985131" quat="0.531959 0.465906 0.466024 0.531765" mass="0.0630136" diaginertia="4.24266e-05 3.5526e-05 2.00009e-05"/>
				<joint name="right_hip_yaw" pos="0 0 0" axis="0 0 1" range="-1.0472 1.0472"/>
				<geom size="0.01875 0.02375 0.0015" pos="-0.03144 0 -0.02375" quat="0.5 0.5 0.5 0.5" type="box"/>
				<geom size="0.01875 0.02375 0.0015" pos="0.0219 0 -0.02375" quat="0.5 -0.5 0.5 -0.5" type="box"/>
				<body name="mx106_block_mir_hip__list_mr67plvazplf9a_hip" pos="0.0234 0 -0.04" quat="0.5 0.5 -0.5 -0.5">
					<inertial pos="0.000527445 -0.0153964 0.00383064" quat="0.996695 -0.0796624 0.0075433 -0.0140338" mass="0.397097" diaginertia="0.000428741 0.000375798 0.000176713"/>
					<joint name="right_hip_roll" pos="0 0 0" axis="0 0 1" range="-0.610865 0.523599"/>
					<geom size="0.0201 0.03255 0.023" pos="0 -0.01805 -0.026" type="box"/>
					<geom size="0.0201 0.03255 0.023" pos="0 -0.01805 0.0234" quat="0.707107 0 -0.707107 0" type="box"/>
					<body name="right_knee_2023" pos="-0.0295 0 0.0234" quat="0.707107 0 0.707107 0">
						<inertial pos="-3.04946e-05 -0.100616 0.0296089" quat="0.722631 0.691234 0.000116647 0.000114696" mass="0.268473" diaginertia="0.000539257 0.000462486 0.000122221"/>
						<joint name="right_hip_pitch" pos="0 0 0" axis="0 0 1" range="-1.5708 1.5708"/>
						<geom size="0.015 0.04825 0.0015" pos="0 -0.03725 -0.0015" quat="0 1 0 0" type="box"/>
						<geom size="0.015 0.04825 0.0015" pos="0 -0.03725 0.057" quat="1 0 0 0" type="box"/>
						<geom size="0.0201 0.03255 0.023" pos="0 -0.12195 0.0295" quat="0 -1 0 0" type="box"/>
						<body name="tibia_2023_2" pos="0 -0.14 0.001" quat="0 0 0 -1">
							<inertial pos="-0.00296199 0.0631406 0.0268398" quat="0.707175 0.706918 -0.00915244 -0.00934946" mass="0.113077" diaginertia="0.000351979 0.00027164 0.000103748"/>
							<joint name="right_knee" pos="0 0 0" axis="0 0 1" range="0 3.14159"/>
							<geom size="0.0202131 0.0850495 0.0015" pos="-0.0062131 0.068951 0.05594" quat="0 0 1 0" type="box"/>
							<geom size="0.0202131 0.0850495 0.0015" pos="-0.0062131 0.068951 -0.0015" quat="0 0 -1 0" type="box"/>
							<body name="mx106_block_ankle__list_0bj1pweadmbeeq_default" pos="0 0.14 0" quat="1 0 0 0">
								<inertial pos="-0.0195724 -0.0153964 0.0290252" quat="-0.0661652 0.699382 0.0464976 0.710158" mass="0.397097" diaginertia="0.000428694 0.000375752 0.000176714"/>
								<joint name="right_ankle_pitch" pos="0 0 0" axis="0 0 1" range="-1.5708 1.5708"/>
								<geom size="0.0201 0.03255 0.023" pos="0 -0.01805 0.0285" quat="0 0 -1 0" type="box"/>
								<geom size="0.0201 0.03255 0.023" pos="-0.0494 -0.01805 0.0285" quat="0.707107 0 0.707107 0" type="box"/>
								<body name="right_foot_" pos="-0.0234 0 0.0285" quat="0 -0.707107 0 -0.707107">
									<inertial pos="-0.00454439 -0.0365542 0.0466461" quat="0.702491 -0.0112519 0.00420004 0.711591" mass="0.281856" diaginertia="0.000922792 0.000718237 0.000264953"/>
									<joint name="right_ankle_roll" pos="0 0 0" axis="0 0 1" range="-0.785398 0.785398"/>
									<geom size="0.02617 0.015 0.003125" pos="0 -0.036875 0.02817" quat="0.5 0.5 0.5 -0.5" type="box"/>
									<geom size="0.008 0.008" pos="-0.0435 -0.0535 -0.03213" quat="0.707107 0.707107 0 0" type="cylinder"/>
									<geom size="0.046 0.0788 0.0015" pos="-0.0055 -0.0415 0.03867" quat="0.707107 -0.707107 0 0" type="box"/>
									<geom size="0.008 0.008" pos="0.0325 -0.0535 -0.03213" quat="0.707107 0.707107 0 0" type="cylinder"/>
									<geom size="0.008 0.008" pos="-0.0435 -0.0535 0.10947" quat="0 0 -0.707107 0.707107" type="cylinder"/>
									<geom size="0.008 0.008" pos="0.0325 -0.0535 0.10947" quat="0 0 -0.707107 0.707107" type="cylinder"/>
								</body>
							</body>
						</body>
					</body>
				</body>
			</body>
		</body>
	</worldbody>
</mujoco>
