<robot name="onshape">
<link name="torso_2023">

<collision>
<origin xyz="0.060389204868665558035 1.4717405121993400189e-07 0.068082299999999984497" rpy="-1.5707963267948958919 1.0318754721533555292e-15 -1.570796326794896558" />
<geometry>
<box size="0.14499999999999999001 0.1155920000000000003 0.0060000000000000001249" />
</geometry>
</collision>

<collision>
<origin xyz="0.020939204868665975412 0.046400147174051414867 0.02200000000001074707" rpy="3.1415926535897691352 -1.3138215008622163751e-14 -1.570796326794896336" />
<geometry>
<box size="0.040199999999999999623 0.061100000000000001532 0.041000000000000001721" />
</geometry>
</collision>

<collision>
<origin xyz="0.020939204868666350112 -0.046399852825948745272 0.02200000000001099687" rpy="3.1415926535897495953 -1.2771348726224209355e-14 -1.5707963267949036634" />
<geometry>
<box size="0.040199999999999999623 0.061100000000000001532 0.041000000000000001721" />
</geometry>
</collision>

<collision>
<origin xyz="0.01583920486865465771 1.471740505627167706e-07 0.15700000000000038924" rpy="-2.0985643641962011544e-15 -2.5607325653630936744e-16 -1.570796326794896558" />
<geometry>
<box size="0.040199999999999999623 0.061100000000000001532 0.041000000000000001721" />
</geometry>
</collision>

<collision>
<origin xyz="-0.059610795131336914709 1.4717404883173641263e-07 0.071917699999998543903" rpy="1.5707963267948952257 7.9211561423418466212e-15 1.570796326794896558" />
<geometry>
<box size="0.14499999999999999001 0.1155920000000000003 0.0060000000000000001249" />
</geometry>
</collision>

<collision>
<origin xyz="0.010839204868674762183 0.056000147174040608433 0.16400000000000933276" rpy="-1.5707963267948805708 -1.5707963267948898967 0" />
<geometry>
<box size="0.040199999999999999623 0.061100000000000001532 0.041000000000000001721" />
</geometry>
</collision>

<collision>
<origin xyz="0.010839204868674713611 -0.055999852825940207857 0.16400000000001024869" rpy="1.5707963267948803487 1.5707963267948898967 0" />
<geometry>
<box size="0.040199999999999999623 0.061100000000000001532 0.041000000000000001721" />
</geometry>
</collision>
<visual>
<origin xyz="0 0 0" rpy="0 -0 0" />
<geometry>
<mesh filename="torso_2023_visual.stl" />
</geometry>
<material name="torso_2023_material">
<color rgba="0.1989915035131896992 0.20531734779085586418 0.21164319206852200139 1.0" />
</material>
</visual>
<inertial>
<origin xyz="0.0015648355792355680277 6.7326172377745458603e-05 0.070745013494479591643" rpy="0 0 0" />
<mass value="3.275156416662882819" />
<inertia ixx="0.019938644668998903309" ixy="0.00017941416398604062153" ixz="0.00023297474433931533158" iyy="0.018854191811137354512" iyz="-0.00022931010479271859547" izz="0.012649651833892626429" />
</inertial>
</link>

<link name="head_base">
<inertial>
<origin xyz="0 0 0" rpy="0 0 0" />
<mass value="1e-9" />
<inertia ixx="0" ixy="0" ixz="0" iyy="0" iyz="0" izz="0" />
</inertial>
</link>
<joint name="head_base_frame" type="fixed">
<origin xyz="0.033389204868654910607 1.4717405055631460442e-07 0.18300000000001087619" rpy="-1.2246467991473633145e-16 -2.2088105346187814874e-29 1.4393641492882479269e-28" />
<parent link="torso_2023" />
<child link="head_base" />
<axis xyz="0 0 0" />
</joint>

<link name="trunk">
<inertial>
<origin xyz="0 0 0" rpy="0 0 0" />
<mass value="1e-9" />
<inertia ixx="0" ixy="0" ixz="0" iyy="0" iyz="0" izz="0" />
</inertial>
</link>
<joint name="trunk_frame" type="fixed">
<origin xyz="0.060889204868665502968 1.4717405119935517762e-07 0.0024999999999999996184" rpy="-8.2672622867162037207e-28 -0 -2.2402855000300105724e-59" />
<parent link="torso_2023" />
<child link="trunk" />
<axis xyz="0 0 0" />
</joint>

<link name="u_neck">

<collision>
<origin xyz="0.024999999999999980571 1.9039197994973640794e-16 0.032901041851021120554" rpy="1.5707963267948976682 3.8555576742675836556e-29 -1.5707963267948958919" />
<geometry>
<box size="0.02999999999999999889 0.065802000000000013258 0.0030000000000000000625" />
</geometry>
</collision>

<collision>
<origin xyz="-0.024999999999999970163 -1.3321288525649692514e-17 0.032901041851021231577" rpy="1.570796326794896558 -1.1537090738856905291e-29 1.5707963267948970021" />
<geometry>
<box size="0.02999999999999999889 0.065802000000000013258 0.0030000000000000000625" />
</geometry>
</collision>

<collision>
<origin xyz="0 0 0.0031250000000000001735" rpy="3.141592653589793116 -0 -2.7345846813906869054e-32" />
<geometry>
<box size="0.049000000000000001887 0.02999999999999999889 0.0062500000000000003469" />
</geometry>
</collision>
<visual>
<origin xyz="0 0 0" rpy="0 -0 0" />
<geometry>
<mesh filename="u_neck_visual.stl" />
</geometry>
<material name="u_neck_material">
<color rgba="0.30196078431372547213 0.30196078431372547213 0.30196078431372547213 1.0" />
</material>
</visual>
<inertial>
<origin xyz="4.9752393097228002441e-18 5.2566512831789962461e-17 0.020633402679855913225" rpy="0 0 0" />
<mass value="0.054479900613359222294" />
<inertia ixx="3.0578702573708504834e-05" ixy="-1.3594422668539657696e-11" ixz="7.4115382884751279668e-20" iyy="5.1695196768450734476e-05" iyz="-1.3870164511289168052e-20" izz="2.9852490907290876406e-05" />
</inertial>
</link>

<link name="head_2023__field_of_view_false">

<collision>
<origin xyz="-0.0238000000000099729 0.036500000000010031365 -0.0049999999999899950864" rpy="-3.141592653589793116 9.2835736742051706507e-32 -3.141592653589793116" />
<geometry>
<cylinder length="0.0030000000000000000625" radius="0.023500000000000000056" />
</geometry>
</collision>
<collision>
<origin xyz="0.0099999999999900238135 0.036500000000010031365 -0.0049999999999899950864" rpy="-3.141592653589793116 9.2835736742051706507e-32 -3.141592653589793116" />
<geometry>
<box size="0.061600000000000001976 0.047000000000000000111 0.0030000000000000000625" />
</geometry>
</collision>

<collision>
<origin xyz="-0.023799999999999973954 0.036499999999999983846 -0.049000000000000001887" rpy="-3.141592653589793116 9.2835736742051706507e-32 -3.141592653589793116" />
<geometry>
<cylinder length="0.0030000000000000000625" radius="0.023500000000000000056" />
</geometry>
</collision>
<collision>
<origin xyz="0.01000000000000002276 0.036499999999999983846 -0.049000000000000001887" rpy="-3.141592653589793116 9.2835736742051706507e-32 -3.141592653589793116" />
<geometry>
<box size="0.061600000000000001976 0.047000000000000000111 0.0030000000000000000625" />
</geometry>
</collision>

<collision>
<origin xyz="-6.4717011221295137098e-33 -0.017550000000000003098 -0.023499999999999996586" rpy="-4.0588667713456232966e-32 -9.2835736742051706507e-32 3.6977854932378233042e-32" />
<geometry>
<box size="0.040199999999999999623 0.061100000000000001532 0.041000000000000001721" />
</geometry>
</collision>
<visual>
<origin xyz="0 0 0" rpy="0 -0 0" />
<geometry>
<mesh filename="head_2023__field_of_view_false_visual.stl" />
</geometry>
<material name="head_2023__field_of_view_false_material">
<color rgba="0.32045575682762950098 0.31487383381853989439 0.29812806479127107462 1.0" />
</material>
</visual>
<inertial>
<origin xyz="-0.00013983749463300954204 0.0039774654891464892789 -0.023375717796835469853" rpy="0 0 0" />
<mass value="0.25726509819793869083" />
<inertia ixx="0.00025168424048600053673" ixy="5.0191177966145026165e-06" ixz="6.2758237416004872282e-07" iyy="0.00010580107060652920782" iyz="3.6478758293029893322e-06" izz="0.00024599473978848055951" />
</inertial>
</link>

<link name="camera">
<inertial>
<origin xyz="0 0 0" rpy="0 0 0" />
<mass value="1e-9" />
<inertia ixx="0" ixy="0" ixz="0" iyy="0" iyz="0" izz="0" />
</inertial>
</link>
<joint name="camera_frame" type="fixed">
<origin xyz="-0.024933000004024159779 0.033500000000055624172 -0.023500000000000024342" rpy="3.1415926535897926719 1.5707963267948934494 0" />
<parent link="head_2023__field_of_view_false" />
<child link="camera" />
<axis xyz="0 0 0" />
</joint>

<joint name="head_pitch" type="revolute">
<origin xyz="-0.023499999999999954953 -4.8572257327350598644e-17 0.058302041851021751961" rpy="1.570796326794896558 1.1537090738857285042e-29 -1.5707963267949005548" />
<parent link="u_neck" />
<child link="head_2023__field_of_view_false" />
<axis xyz="0 0 1" />
<limit effort="10" velocity="6" lower="-0.785398163397448279" upper="1.570796326794896558" />
<joint_properties friction="0.0" />
</joint>

<joint name="head_yaw" type="revolute">
<origin xyz="0.033389204868654910607 1.4717405055617108527e-07 0.18050000000001084621" rpy="7.2164496600569305242e-16 -2.5607325488194868468e-16 -1.5707963267948958919" />
<parent link="torso_2023" />
<child link="u_neck" />
<axis xyz="0 0 1" />
<limit effort="10" velocity="6" lower="-2.0943951023931952626" upper="2.0943951023931952626" />
<joint_properties friction="0.0" />
</joint>

<link name="u_shoulder_2023">

<collision>
<origin xyz="2.9143354396410359186e-16 2.7755575615628913511e-17 0.0071250000000000037262" rpy="-3.141592653589793116 1.6724317820075083247e-31 -2.4033544272240996515e-33" />
<geometry>
<box size="0.049000000000000001887 0.02999999999999999889 0.0062500000000000003469" />
</geometry>
</collision>
<visual>
<origin xyz="0 0 0" rpy="0 -0 0" />
<geometry>
<mesh filename="u_shoulder_2023_visual.stl" />
</geometry>
<material name="u_shoulder_2023_material">
<color rgba="0.30196078431372547213 0.30196078431372547213 0.30196078431372547213 1.0" />
</material>
</visual>
<inertial>
<origin xyz="1.8232168344783914634e-16 0.0036464153452487211779 0.021400275306226044375" rpy="0 0 0" />
<mass value="0.075104257301521246126" />
<inertia ixx="3.3576612252240278344e-05" ixy="2.45704488381832511e-19" ixz="-1.0100867896007531543e-19" iyy="5.6855013760483194411e-05" iyz="-1.6441190837762353295e-06" izz="4.5579632407482574292e-05" />
</inertial>
</link>

<link name="left_humerus">

<collision>
<origin xyz="5.1535325302692628554e-19 -0.017549999999999187777 -0.02350000000001000941" rpy="1.1349789930214285673e-16 7.4033329793110606974e-29 6.0880324679154251917e-17" />
<geometry>
<box size="0.040199999999999999623 0.061100000000000001532 0.041000000000000001721" />
</geometry>
</collision>

<collision>
<origin xyz="-9.8237390444566585757e-15 -0.10450000000001577471 -0.040000000000000250633" rpy="3.141592653589793116 9.9803458132119403788e-16 -1.5707963267948958919" />
<geometry>
<box size="0.10499999999999999611 0.02999999999999999889 0.0030000000000000000625" />
</geometry>
</collision>
<visual>
<origin xyz="0 0 0" rpy="0 -0 0" />
<geometry>
<mesh filename="left_humerus_visual.stl" />
</geometry>
<material name="left_humerus_material">
<color rgba="0.26470081700903541622 0.26470081700903541622 0.26470081700903541622 1.0" />
</material>
</visual>
<inertial>
<origin xyz="0.00034063685431862979203 -0.052268486590341223241 -0.026882157242683241832" rpy="0 0 0" />
<mass value="0.24350225743978931581" />
<inertia ixx="0.00077073676321792153505" ixy="5.6780808115084161313e-06" ixz="9.5781652228323994906e-07" iyy="8.4206620691435125122e-05" iyz="-5.8757422747890845406e-05" izz="0.0007520574846905521112" />
</inertial>
</link>

<link name="radius_v2">

<collision>
<origin xyz="2.3106516700011070498e-15 -0.14960000000000389653 -0.042000000000007142731" rpy="8.5789493427633097606e-16 -1.4393969514836101488e-14 -1.5707963267948807928" />
<geometry>
<cylinder length="0.0030000000000000000625" radius="0.040000000000000000833" />
</geometry>
</collision>
<collision>
<origin xyz="9.7418507733165615419e-16 -0.064975600000001590417 -0.042000000000008357037" rpy="8.5789493427633097606e-16 -1.4393969514836101488e-14 -1.5707963267948807928" />
<geometry>
<box size="0.099551199999999992474 0.041200000000000000511 0.0030000000000000000625" />
</geometry>
</collision>

<collision>
<origin xyz="2.6328800239494788571e-16 -0.017550000000000356981 -0.023500000000009312051" rpy="-1.4628061606333769143e-14 -1.72913973246405356e-15 -3.3085907960557563128e-24" />
<geometry>
<box size="0.040199999999999999623 0.061100000000000001532 0.041000000000000001721" />
</geometry>
</collision>

<collision>
<origin xyz="2.2343238370581275376e-15 -0.14960000000000436837 -0.0050000000000077760021" rpy="1.5801403290850097167e-15 -1.4137400195363193623e-14 -1.5707963267948807928" />
<geometry>
<cylinder length="0.0030000000000000000625" radius="0.040000000000000000833" />
</geometry>
</collision>
<collision>
<origin xyz="8.9785724466864041907e-16 -0.064975600000000355294 -0.0050000000000089729613" rpy="1.5801403290850097167e-15 -1.4137400195363193623e-14 -1.5707963267948807928" />
<geometry>
<box size="0.099551199999999992474 0.041200000000000000511 0.0030000000000000000625" />
</geometry>
</collision>
<visual>
<origin xyz="0 0 0" rpy="0 -0 0" />
<geometry>
<mesh filename="radius_v2_visual.stl" />
</geometry>
<material name="radius_v2_material">
<color rgba="0.21421337674205656598 0.21421337674205656598 0.21421337674205656598 1.0" />
</material>
</visual>
<inertial>
<origin xyz="7.9817140183367828263e-05 -0.055690458705458058264 -0.023433267774075318413" rpy="0 0 0" />
<mass value="0.25684588818622827722" />
<inertia ixx="0.00093724061814984944117" ixy="-7.9268562208035292056e-07" ixz="6.139564055294468462e-07" iyy="0.00013059673215064026642" iyz="1.978663300161534759e-06" izz="0.00094705350609366112033" />
</inertial>
</link>

<joint name="left_elbow" type="revolute">
<origin xyz="0.023499999999999049427 -0.14200000000002432898 -0.0024999999999903571579" rpy="1.1420760646645946157e-16 1.5707963267948905628 0" />
<parent link="left_humerus" />
<child link="radius_v2" />
<axis xyz="0 0 1" />
<limit effort="10" velocity="6" lower="-2.7925268031909271649" upper="0.26179938779914940783" />
<joint_properties friction="0.0" />
</joint>

<joint name="left_shoulder_roll" type="revolute">
<origin xyz="0.02350000000000028802 0.030000000000000054401 0.030000000000000012768" rpy="-1.570796326794896336 -1.3089969389957472057 -1.5707963267948781283" />
<parent link="u_shoulder_2023" />
<child link="left_humerus" />
<axis xyz="0 0 1" />
<limit effort="10" velocity="6" lower="-0.26179938779914940783" upper="1.3089969389957472057" />
<joint_properties friction="0.0" />
</joint>

<joint name="left_shoulder_pitch" type="revolute">
<origin xyz="0.02838920486867376608 0.079500147174041552178 0.16400000000000961031" rpy="-1.5707963267948972241 5.4610004281647751681e-16 -1.1318824364894941469e-14" />
<parent link="torso_2023" />
<child link="u_shoulder_2023" />
<axis xyz="0 0 1" />
<limit effort="10" velocity="6" lower="-2.1816615649929120835" upper="2.1816615649929120835" />
<joint_properties friction="0.0" />
</joint>

<link name="u_shoulder_2023_2">

<collision>
<origin xyz="-6.0965844572341306327e-33 2.7755575615629246311e-17 -0.007125000000000017604" rpy="1.0710301291113360143e-28 2.523751638323538339e-31 -2.7117093615639733553e-31" />
<geometry>
<box size="0.049000000000000001887 0.02999999999999999889 0.0062500000000000003469" />
</geometry>
</collision>
<visual>
<origin xyz="0 0 0" rpy="0 -0 0" />
<geometry>
<mesh filename="u_shoulder_2023_2_visual.stl" />
</geometry>
<material name="u_shoulder_2023_2_material">
<color rgba="0.30196078431372547213 0.30196078431372547213 0.30196078431372547213 1.0" />
</material>
</visual>
<inertial>
<origin xyz="-8.9096950342566447563e-19 -0.0036464153452484215044 -0.021400275306226186622" rpy="0 0 0" />
<mass value="0.075104257301521246126" />
<inertia ixx="3.3576612252239986965e-05" ixy="1.3539292266267956982e-20" ixz="3.5089001584499433968e-21" iyy="5.6855013760483092767e-05" iyz="-1.6441190837762569288e-06" izz="4.557963240748243199e-05" />
</inertial>
</link>

<link name="right_humerus">

<collision>
<origin xyz="-2.2551405187698492227e-17 -0.10450000000000948808 -0.040000000000000042466" rpy="-3.1415926535897922278 9.604334409304415985e-16 -1.5707963267948972241" />
<geometry>
<box size="0.10499999999999999611 0.02999999999999999889 0.0030000000000000000625" />
</geometry>
</collision>

<collision>
<origin xyz="1.270652739318305808e-19 -0.017550000000000016975 -0.023499999999999996586" rpy="-1.7916779872509620224e-31 4.9939169036483919336e-31 -3.1007302914032570076e-17" />
<geometry>
<box size="0.040199999999999999623 0.061100000000000001532 0.041000000000000001721" />
</geometry>
</collision>
<visual>
<origin xyz="0 0 0" rpy="0 -0 0" />
<geometry>
<mesh filename="right_humerus_visual.stl" />
</geometry>
<material name="right_humerus_material">
<color rgba="0.26470081700903541622 0.26470081700903541622 0.26470081700903541622 1.0" />
</material>
</visual>
<inertial>
<origin xyz="-0.00017225481453279987282 -0.052268486158451560319 -0.026866891908496049607" rpy="0 0 0" />
<mass value="0.2435022574397892603" />
<inertia ixx="0.0007707618315275926741" ixy="-7.1231336283564645489e-06" ixz="1.2804627548291555793e-07" iyy="8.4252737154473183556e-05" iyz="-5.8783325637439840319e-05" izz="0.00075207849509710599043" />
</inertial>
</link>

<link name="radius_v2_2">

<collision>
<origin xyz="-1.0189765697887776311e-15 0.14960000000000850395 0.0050000000000102774733" rpy="3.1415926535897917837 1.5636190652210659677e-15 1.5707963267949021091" />
<geometry>
<cylinder length="0.0030000000000000000625" radius="0.040000000000000000833" />
</geometry>
</collision>
<collision>
<origin xyz="-5.6096077782891871578e-16 0.064975600000003658208 0.0050000000000104101797" rpy="3.1415926535897917837 1.5636190652210659677e-15 1.5707963267949021091" />
<geometry>
<box size="0.099551199999999992474 0.041200000000000000511 0.0030000000000000000625" />
</geometry>
</collision>

<collision>
<origin xyz="-8.6636253726624205175e-16 0.14960000000000844844 0.042000000000012110979" rpy="3.1415926535897922278 2.0442758469186439441e-15 1.5707963267949023312" />
<geometry>
<cylinder length="0.0030000000000000000625" radius="0.040000000000000000833" />
</geometry>
</collision>
<collision>
<origin xyz="-3.9190515277449251122e-16 0.064975600000003672085 0.042000000000012284451" rpy="3.1415926535897922278 2.0442758469186439441e-15 1.5707963267949023312" />
<geometry>
<box size="0.099551199999999992474 0.041200000000000000511 0.0030000000000000000625" />
</geometry>
</collision>

<collision>
<origin xyz="-1.1970008317875247656e-16 0.017550000000001033523 0.023500000000011313922" rpy="3.1415926535897913396 1.1729299448985399785e-17 3.1428563154296863991e-18" />
<geometry>
<box size="0.040199999999999999623 0.061100000000000001532 0.041000000000000001721" />
</geometry>
</collision>
<visual>
<origin xyz="0 0 0" rpy="0 -0 0" />
<geometry>
<mesh filename="radius_v2_2_visual.stl" />
</geometry>
<material name="radius_v2_2_material">
<color rgba="0.21421337674205656598 0.21421337674205656598 0.21421337674205656598 1.0" />
</material>
</visual>
<inertial>
<origin xyz="7.981714018216070467e-05 0.055690458705459910949 0.023433267774077819884" rpy="0 0 0" />
<mass value="0.25684588818622816619" />
<inertia ixx="0.0009372406181499015913" ixy="7.9268562209457862715e-07" ixz="-6.1395640552935060209e-07" iyy="0.00013059673215065002424" iyz="1.9786633001541312675e-06" izz="0.00094705350609373321977" />
</inertial>
</link>

<joint name="right_elbow" type="revolute">
<origin xyz="-0.02350000000000931899 -0.14200000000001897216 -0.0024999999999904057302" rpy="-3.141592653589793116 -1.5707963267948936714 0" />
<parent link="right_humerus" />
<child link="radius_v2_2" />
<axis xyz="0 0 1" />
<limit effort="10" velocity="6" lower="-2.7925268031909271649" upper="0.26179938779914940783" />
<joint_properties friction="0.0" />
</joint>

<joint name="right_shoulder_roll" type="revolute">
<origin xyz="-0.023499999999989990701 -0.029999999999999943379 -0.030000000000000026645" rpy="1.570796326794896558 -1.3089969389957472057 -1.5707963267948921171" />
<parent link="u_shoulder_2023_2" />
<child link="right_humerus" />
<axis xyz="0 0 1" />
<limit effort="10" velocity="6" lower="-1.3089969389957472057" upper="0.26179938779914940783" />
<joint_properties friction="0.0" />
</joint>

<joint name="right_shoulder_pitch" type="revolute">
<origin xyz="0.028389204868675101817 -0.079499852825939923417 0.16400000000001035971" rpy="1.5707963267914575312 6.7723604502158104352e-15 -3.1415926535897766847" />
<parent link="torso_2023" />
<child link="u_shoulder_2023_2" />
<axis xyz="0 0 1" />
<limit effort="10" velocity="6" lower="-2.1816615649929120835" upper="2.1816615649929120835" />
<joint_properties friction="0.0" />
</joint>

<link name="u_block_2023">

<collision>
<origin xyz="-0.031440000000000002667 0 -0.023750000000000010686" rpy="1.570796326794896558 1.5375480027067150408e-30 1.570796326794896558" />
<geometry>
<box size="0.037499999999999998612 0.047500000000000000555 0.0030000000000000000625" />
</geometry>
</collision>

<collision>
<origin xyz="0.021899999999999981981 6.9388939039072283776e-18 -0.023750000000000014155" rpy="-1.570796326794896558 4.7733392390613801031e-30 -1.5707963267948970021" />
<geometry>
<box size="0.037499999999999998612 0.047500000000000000555 0.0030000000000000000625" />
</geometry>
</collision>
<visual>
<origin xyz="0 0 0" rpy="0 -0 0" />
<geometry>
<mesh filename="u_block_2023_visual.stl" />
</geometry>
<material name="u_block_2023_material">
<color rgba="0.30196078431372552764 0.30196078431372552764 0.30196078431372552764 1.0" />
</material>
</visual>
<inertial>
<origin xyz="-0.0050953192241065571599 -8.4419506225231468697e-07 -0.0098513101413465805484" rpy="0 0 0" />
<mass value="0.063013635376408722033" />
<inertia ixx="2.0269428345457467326e-05" ixy="1.5200724677905147079e-09" ixz="-2.023932140462646351e-06" iyy="4.242656866493677134e-05" iyz="-2.0044169173988357712e-09" izz="3.5257506291535481555e-05" />
</inertial>
</link>

<link name="mx106_block_hip__list_0bj1pweadmbeeq_hip">

<collision>
<origin xyz="6.9388939039072245258e-18 -0.018050000000000003542 -0.025999999999999998807" rpy="4.4232993409402326246e-31 -1.0829362358345484462e-30 -1.5003599116030702926e-33" />
<geometry>
<box size="0.040199999999999999623 0.065099999999999991207 0.045999999999999999223" />
</geometry>
</collision>

<collision>
<origin xyz="-5.587197371426131568e-16 -0.018050000000003129513 0.023400000000023360447" rpy="4.5186077102243625071e-14 1.5707963267948559238 0" />
<geometry>
<box size="0.040199999999999999623 0.065099999999999991207 0.045999999999999999223" />
</geometry>
</collision>
<visual>
<origin xyz="0 0 0" rpy="0 -0 0" />
<geometry>
<mesh filename="mx106_block_hip__list_0bj1pweadmbeeq_hip_visual.stl" />
</geometry>
<material name="mx106_block_hip__list_0bj1pweadmbeeq_hip_material">
<color rgba="0.30196078431372547213 0.30196078431372547213 0.30196078431372547213 1.0" />
</material>
</visual>
<inertial>
<origin xyz="-0.00052516692186616454729 -0.015396401985203245905 0.0038277888729035540634" rpy="0 0 0" />
<mass value="0.39709667579512258895" />
<inertia ixx="0.00042858306123093477778" ixy="2.0805509671368810993e-06" ixz="4.1041475610358611124e-06" iyy="0.00037079320782765960805" iyz="-3.1142636673186421933e-05" izz="0.00018178880431223535955" />
</inertial>
</link>

<link name="left_knee_2023">

<collision>
<origin xyz="1.4913596831999887702e-16 0.12195000000002188811 -0.029500000000001705414" rpy="-1.2212453270869762219e-15 3.64326624424644987e-14 8.8149932579980472257e-15" />
<geometry>
<box size="0.040199999999999999623 0.065099999999999991207 0.045999999999999999223" />
</geometry>
</collision>

<collision>
<origin xyz="7.3160900016631066617e-16 0.037249999999999887368 -0.056999999999998170186" rpy="3.1415926535897678029 8.0383616429810889004e-14 4.6345982414074165367e-14" />
<geometry>
<box size="0.02999999999999999889 0.096500000000000002442 0.0030000000000000000625" />
</geometry>
</collision>

<collision>
<origin xyz="4.3368086899420292916e-19 0.037250000000000005329 0.0015000000000000026333" rpy="0 -1.4191589699425682925e-32 0" />
<geometry>
<box size="0.02999999999999999889 0.096500000000000002442 0.0030000000000000000625" />
</geometry>
</collision>
<visual>
<origin xyz="0 0 0" rpy="0 -0 0" />
<geometry>
<mesh filename="left_knee_2023_visual.stl" />
</geometry>
<material name="left_knee_2023_material">
<color rgba="0.30196078431372547213 0.30196078431372547213 0.30196078431372547213 1.0" />
</material>
</visual>
<inertial>
<origin xyz="-3.0494550053121577383e-05 0.10061564187093975653 -0.029622786648481010119" rpy="0 0 0" />
<mass value="0.26847272690346352109" />
<inertia ixx="0.00053925645022024357514" ixy="-1.3631373190137804101e-07" ixz="5.8241303226778181552e-09" iyy="0.00012289105714449451243" iyz="1.5058327493549626962e-05" izz="0.00046181552279401692166" />
</inertial>
</link>

<link name="tibia_2023">

<collision>
<origin xyz="-0.0062131000000000009137 0.068950999999999998402 0.0015000000000000026333" rpy="-3.141592653589793116 1.4713170045275157975e-31 3.141592653589793116" />
<geometry>
<box size="0.04042620000000000241 0.1700990000000000002 0.0030000000000000000625" />
</geometry>
</collision>

<collision>
<origin xyz="-0.0062131000000001275485 0.068951000000002274359 -0.055939999999999795444" rpy="3.141592653589793116 2.953628240564971051e-31 -3.141592653589793116" />
<geometry>
<box size="0.04042620000000000241 0.1700990000000000002 0.0030000000000000000625" />
</geometry>
</collision>
<visual>
<origin xyz="0 0 0" rpy="0 -0 0" />
<geometry>
<mesh filename="tibia_2023_visual.stl" />
</geometry>
<material name="tibia_2023_material">
<color rgba="0.30196078431372547213 0.30196078431372547213 0.30196078431372547213 1.0" />
</material>
</visual>
<inertial>
<origin xyz="-0.0029619942214337505876 0.06314054434257244941 -0.026839813800166509999" rpy="0 0 0" />
<mass value="0.11307719724589511412" />
<inertia ixx="0.00035180943614669511364" ixy="-6.4923421817825492723e-06" ixz="2.0403709312578429582e-08" iyy="0.00010391794921028493206" iyz="-6.1996439046809369065e-08" izz="0.00027164029097416139951" />
</inertial>
</link>

<link name="mx106_block_mir_ankle">

<collision>
<origin xyz="-2.4835481882836499138e-15 0.018050000000000225586 -0.028500000000006839307" rpy="-1.0530465392209247395e-13 -2.3567953144620554086e-14 3.1415926535897851224" />
<geometry>
<box size="0.040199999999999999623 0.065099999999999991207 0.045999999999999999223" />
</geometry>
</collision>

<collision>
<origin xyz="0.049400000000019511637 0.018050000000001779898 -0.028500000000009691192" rpy="-3.1415926535897917837 1.5707963267948958919 0" />
<geometry>
<box size="0.040199999999999999623 0.065099999999999991207 0.045999999999999999223" />
</geometry>
</collision>
<visual>
<origin xyz="0 0 0" rpy="0 -0 0" />
<geometry>
<mesh filename="mx106_block_mir_ankle_visual.stl" />
</geometry>
<material name="mx106_block_mir_ankle_material">
<color rgba="0.30196078431372547213 0.30196078431372547213 0.30196078431372547213 1.0" />
</material>
</visual>
<inertial>
<origin xyz="0.019569546325788379076 0.015396401985194102177 -0.02902744472631435535" rpy="0 0 0" />
<mass value="0.39709667579512264446" />
<inertia ixx="0.00018178785236498012402" ixy="-3.1147027124168096901e-05" ixz="-4.0741771018149064068e-06" iyy="0.00037083367389992462479" iyz="-2.0892224411081638081e-06" izz="0.00042862447925065604113" />
</inertial>
</link>

<link name="left_foot___list_t0v6opd9rekumc_default">

<collision>
<origin xyz="0.043500000000002883582 -0.053500000000002705114 -0.032129999999995370596" rpy="1.5707963267948901187 -2.9167640525074148081e-14 -3.8626551028816556689e-14" />
<geometry>
<cylinder length="0.016000000000000000333" radius="0.0080000000000000001665" />
</geometry>
</collision>

<collision>
<origin xyz="1.4571677198205179593e-15 -0.03687500000000079603 0.028170000000003289631" rpy="1.5707963267949351938 1.570796326794866804 0" />
<geometry>
<box size="0.052340000000000004576 0.02999999999999999889 0.0062500000000000003469" />
</geometry>
</collision>

<collision>
<origin xyz="-0.032499999999997551681 -0.053499999999999818534 -0.032129999999997493898" rpy="1.5707963267948901187 -2.9167640525074148081e-14 -3.8626551028816556689e-14" />
<geometry>
<cylinder length="0.016000000000000000333" radius="0.0080000000000000001665" />
</geometry>
</collision>

<collision>
<origin xyz="0.043499999999998789635 -0.053500000000001872447 0.10947000000000448039" rpy="-1.5707963267948901187 2.9167640525074148081e-14 3.1415926535897544802" />
<geometry>
<cylinder length="0.016000000000000000333" radius="0.0080000000000000001665" />
</geometry>
</collision>

<collision>
<origin xyz="0.0055000000000009164822 -0.041500000000000925038 0.038670000000003486307" rpy="-1.5707963267949029973 -2.9122537714698807895e-14 -3.862655106405614715e-14" />
<geometry>
<box size="0.091999999999999998446 0.1575999999999999901 0.0030000000000000000625" />
</geometry>
</collision>

<collision>
<origin xyz="-0.032500000000001520728 -0.053499999999998930356 0.10947000000000238484" rpy="-1.5707963267948901187 2.9167640525074148081e-14 3.1415926535897544802" />
<geometry>
<cylinder length="0.016000000000000000333" radius="0.0080000000000000001665" />
</geometry>
</collision>
<visual>
<origin xyz="0 0 0" rpy="0 -0 0" />
<geometry>
<mesh filename="left_foot___list_t0v6opd9rekumc_default_visual.stl" />
</geometry>
<material name="left_foot___list_t0v6opd9rekumc_default_material">
<color rgba="0.30196078431372547213 0.30093481115542580762 0.2985408737860601458 1.0" />
</material>
</visual>
<inertial>
<origin xyz="0.0045444467896919357036 -0.036554210534013815981 0.046646141434125931724" rpy="0 0 0" />
<mass value="0.28185582496698080579" />
<inertia ixx="0.00071822426056174183337" ixy="2.5091093396115026619e-06" ixz="-4.6415033481459236795e-06" iyy="0.00092244501368009279314" iyz="-1.4353691871045097886e-05" izz="0.00026531274718818537118" />
</inertial>
</link>

<link name="left_foot">
<inertial>
<origin xyz="0 0 0" rpy="0 0 0" />
<mass value="1e-9" />
<inertia ixx="0" ixy="0" ixz="0" iyy="0" iyz="0" izz="0" />
</inertial>
</link>
<joint name="left_foot_frame" type="fixed">
<origin xyz="0.003000000000001674938 -0.061500000000000831779 0.036170000000003560414" rpy="-1.5707963267949325292 -1.570796326794866804 0" />
<parent link="left_foot___list_t0v6opd9rekumc_default" />
<child link="left_foot" />
<axis xyz="0 0 0" />
</joint>

<link name="left_ps_0">
<inertial>
<origin xyz="0 0 0" rpy="0 0 0" />
<mass value="1e-9" />
<inertia ixx="0" ixy="0" ixz="0" iyy="0" iyz="0" izz="0" />
</inertial>
</link>
<joint name="left_ps_0_frame" type="fixed">
<origin xyz="-0.032500000000001291744 -0.061499999999999999112 0.10947000000000527142" rpy="-1.5707963267949425212 -1.570796326794866804 0" />
<parent link="left_foot___list_t0v6opd9rekumc_default" />
<child link="left_ps_0" />
<axis xyz="0 0 0" />
</joint>

<link name="left_ps_1">
<inertial>
<origin xyz="0 0 0" rpy="0 0 0" />
<mass value="1e-9" />
<inertia ixx="0" ixy="0" ixz="0" iyy="0" iyz="0" izz="0" />
</inertial>
</link>
<joint name="left_ps_1_frame" type="fixed">
<origin xyz="-0.032499999999997197797 -0.061500000000000942801 -0.032129999999995828563" rpy="-1.5707963267949387465 -1.570796326794866804 0" />
<parent link="left_foot___list_t0v6opd9rekumc_default" />
<child link="left_ps_1" />
<axis xyz="0 0 0" />
</joint>

<link name="left_ps_2">
<inertial>
<origin xyz="0 0 0" rpy="0 0 0" />
<mass value="1e-9" />
<inertia ixx="0" ixy="0" ixz="0" iyy="0" iyz="0" izz="0" />
</inertial>
</link>
<joint name="left_ps_2_frame" type="fixed">
<origin xyz="0.043500000000002099487 -0.06150000000000377387 -0.032129999999993760773" rpy="-1.5707963267949387465 -1.570796326794866804 0" />
<parent link="left_foot___list_t0v6opd9rekumc_default" />
<child link="left_ps_2" />
<axis xyz="0 0 0" />
</joint>

<link name="left_ps_3">
<inertial>
<origin xyz="0 0 0" rpy="0 0 0" />
<mass value="1e-9" />
<inertia ixx="0" ixy="0" ixz="0" iyy="0" iyz="0" izz="0" />
</inertial>
</link>
<joint name="left_ps_3_frame" type="fixed">
<origin xyz="0.043499999999997894518 -0.061500000000002830181 0.10947000000000735309" rpy="-1.5707963267949436315 -1.570796326794866804 0" />
<parent link="left_foot___list_t0v6opd9rekumc_default" />
<child link="left_ps_3" />
<axis xyz="0 0 0" />
</joint>

<joint name="left_ankle_roll" type="revolute">
<origin xyz="0.023400000000019464258 1.7763568394002504647e-15 -0.028500000000009864665" rpy="-1.3731090952941476011e-15 -1.5707963267948954478 0" />
<parent link="mx106_block_mir_ankle" />
<child link="left_foot___list_t0v6opd9rekumc_default" />
<axis xyz="0 0 1" />
<limit effort="10" velocity="6" lower="-0.785398163397448279" upper="0.785398163397448279" />
<joint_properties friction="0.0" />
</joint>

<joint name="left_ankle_pitch" type="revolute">
<origin xyz="1.3877787807814456755e-17 0.14000000000000001332 1.3877787807814456755e-17" rpy="-4.5044050613495349813e-16 1.7248535108951566065e-30 3.141592653589793116" />
<parent link="tibia_2023" />
<child link="mx106_block_mir_ankle" />
<axis xyz="0 0 1" />
<limit effort="10" velocity="6" lower="-1.570796326794896558" upper="1.570796326794896558" />
<joint_properties friction="0.0" />
</joint>

<joint name="left_knee" type="revolute">
<origin xyz="7.6197728682281251622e-16 0.14000000000002149614 -0.00099999999999096644832" rpy="-3.3306690077040597037e-16 1.8197249262996517094e-14 4.266444745766884715e-15" />
<parent link="left_knee_2023" />
<child link="tibia_2023" />
<axis xyz="0 0 1" />
<limit effort="10" velocity="6" lower="-0" upper="3.141592653589793116" />
<joint_properties friction="0.0" />
</joint>

<joint name="left_hip_pitch" type="revolute">
<origin xyz="0.029500000000009969636 1.5820678100908480701e-15 0.023400000000016792784" rpy="3.1415926535897451544 -1.5707963267948954478 0" />
<parent link="mx106_block_hip__list_0bj1pweadmbeeq_hip" />
<child link="left_knee_2023" />
<axis xyz="0 0 1" />
<limit effort="10" velocity="6" lower="-1.570796326794896558" upper="1.570796326794896558" />
<joint_properties friction="0.0" />
</joint>

<joint name="left_hip_roll" type="revolute">
<origin xyz="0.023399999999999983313 0 -0.040000000000000021649" rpy="1.570796326794896558 -4.8039640370581368107e-14 -1.5707963267949467401" />
<parent link="u_block_2023" />
<child link="mx106_block_hip__list_0bj1pweadmbeeq_hip" />
<axis xyz="0 0 1" />
<limit effort="10" velocity="6" lower="-0.52359877559829881566" upper="0.61086523819801530344" />
<joint_properties friction="0.0" />
</joint>

<joint name="left_hip_yaw" type="revolute">
<origin xyz="0.0033892048686650078082 0.046400147174060754618 -0.021000000000001697864" rpy="4.8006866350193497818e-14 1.5262888187140617583e-14 -3.1415926535897269467" />
<parent link="torso_2023" />
<child link="u_block_2023" />
<axis xyz="0 0 1" />
<limit effort="10" velocity="6" lower="-1.0471975511965976313" upper="1.0471975511965976313" />
<joint_properties friction="0.0" />
</joint>

<link name="u_block_2023_2">

<collision>
<origin xyz="-0.031440000000000016545 -4.4408920985006261617e-16 -0.023750000000000093953" rpy="1.570796326794896558 6.2302052208490232145e-29 1.570796326794896558" />
<geometry>
<box size="0.037499999999999998612 0.047500000000000000555 0.0030000000000000000625" />
</geometry>
</collision>

<collision>
<origin xyz="0.021900000000000009737 -7.2858385991025897965e-17 -0.023750000000000003747" rpy="-1.570796326794896558 -2.3900689497800325527e-28 -1.5707963267948954478" />
<geometry>
<box size="0.037499999999999998612 0.047500000000000000555 0.0030000000000000000625" />
</geometry>
</collision>
<visual>
<origin xyz="0 0 0" rpy="0 -0 0" />
<geometry>
<mesh filename="u_block_2023_2_visual.stl" />
</geometry>
<material name="u_block_2023_2_material">
<color rgba="0.30196078431372552764 0.30196078431372552764 0.30196078431372552764 1.0" />
</material>
</visual>
<inertial>
<origin xyz="-0.0050953192241065866502 -8.4419506236626306475e-07 -0.0098513101413465978956" rpy="0 0 0" />
<mass value="0.063013635376408722033" />
<inertia ixx="2.0269428345457751929e-05" ixy="1.5200724676722477326e-09" ixz="-2.0239321404627314779e-06" iyy="4.2426568664937096601e-05" iyz="-2.0044169174507363915e-09" izz="3.525750629153567129e-05" />
</inertial>
</link>

<link name="mx106_block_mir_hip__list_mr67plvazplf9a_hip">

<collision>
<origin xyz="-7.4674271126216997816e-36 -0.018050000000000007011 -0.025999999999999995337" rpy="-3.7507374077580842329e-31 -9.4629504151230498367e-32 6.120941986080199262e-32" />
<geometry>
<box size="0.040199999999999999623 0.065099999999999991207 0.045999999999999999223" />
</geometry>
</collision>

<collision>
<origin xyz="2.2656388159760541343e-15 -0.01804999999999988558 0.023400000000012195767" rpy="1.5720758028692198942e-13 -1.5707963267948590325 0" />
<geometry>
<box size="0.040199999999999999623 0.065099999999999991207 0.045999999999999999223" />
</geometry>
</collision>
<visual>
<origin xyz="0 0 0" rpy="0 -0 0" />
<geometry>
<mesh filename="mx106_block_mir_hip__list_mr67plvazplf9a_hip_visual.stl" />
</geometry>
<material name="mx106_block_mir_hip__list_mr67plvazplf9a_hip_material">
<color rgba="0.30196078431372547213 0.30196078431372547213 0.30196078431372547213 1.0" />
</material>
</visual>
<inertial>
<origin xyz="0.00052744471950870940816 -0.015396401985192934708 0.0038306435570964812547" rpy="0 0 0" />
<mass value="0.39709667579512253344" />
<inertia ixx="0.00042862743154850450628" ixy="-2.0892223995381237207e-06" ixz="-4.0720577259059815783e-06" iyy="0.00037083662634951943546" iyz="-3.1148188041904293559e-05" izz="0.00018178785251672928847" />
</inertial>
</link>

<link name="right_knee_2023">

<collision>
<origin xyz="-1.2523106465936289283e-32 -0.037250000000000005329 -0.0015000000000000021996" rpy="3.141592653589793116 1.1020642437898762828e-29 3.0330127149397062781e-31" />
<geometry>
<box size="0.02999999999999999889 0.096500000000000002442 0.0030000000000000000625" />
</geometry>
</collision>

<collision>
<origin xyz="2.3679700851343809601e-15 -0.037249999999998291422 0.057000000000000765332" rpy="-1.5521415202872817398e-14 4.3139103400591232513e-14 -2.7929047963232021583e-15" />
<geometry>
<box size="0.02999999999999999889 0.096500000000000002442 0.0030000000000000000625" />
</geometry>
</collision>

<collision>
<origin xyz="3.2510248832152038083e-16 -0.12195000000002542695 0.029499999999993274657" rpy="-3.1415926535897722438 3.1467883854219425843e-14 3.4635488921353952811e-14" />
<geometry>
<box size="0.040199999999999999623 0.065099999999999991207 0.045999999999999999223" />
</geometry>
</collision>
<visual>
<origin xyz="0 0 0" rpy="0 -0 0" />
<geometry>
<mesh filename="right_knee_2023_visual.stl" />
</geometry>
<material name="right_knee_2023_material">
<color rgba="0.30196078431372541662 0.30196078431372541662 0.30196078431372541662 1.0" />
</material>
</visual>
<inertial>
<origin xyz="-3.0494550052434799681e-05 -0.10061564187094176881 0.029608941233490337908" rpy="0 0 0" />
<mass value="0.26847272690346346558" />
<inertia ixx="0.00053925731157976092463" ixy="1.3631373190071542302e-07" ixz="-5.7107785364412577752e-09" iyy="0.00012289191850397730298" iyz="1.5089609413220713563e-05" izz="0.00046181552279405080298" />
</inertial>
</link>

<link name="tibia_2023_2">

<collision>
<origin xyz="-0.0062130999999911512219 0.068950999999997167333 0.055939999999994008406" rpy="-3.141592653589733164 -3.3029134982598432321e-14 -3.1415926535897917837" />
<geometry>
<box size="0.04042620000000000241 0.1700990000000000002 0.0030000000000000000625" />
</geometry>
</collision>

<collision>
<origin xyz="-0.0062131000000000009137 0.068951000000000040036 -0.0015000000000000004649" rpy="-3.141592653589793116 7.2105090570174107409e-30 3.141592653589793116" />
<geometry>
<box size="0.04042620000000000241 0.1700990000000000002 0.0030000000000000000625" />
</geometry>
</collision>
<visual>
<origin xyz="0 0 0" rpy="0 -0 0" />
<geometry>
<mesh filename="tibia_2023_2_visual.stl" />
</geometry>
<material name="tibia_2023_2_material">
<color rgba="0.30196078431372547213 0.30196078431372547213 0.30196078431372547213 1.0" />
</material>
</visual>
<inertial>
<origin xyz="-0.0029619908404728469836 0.063140565164623296823 0.02683982313489245014" rpy="0 0 0" />
<mass value="0.11307719724589511412" />
<inertia ixx="0.00035180944356699760459" ixy="-6.4923416167470600363e-06" ixz="-2.0382960514664992692e-08" iyy="0.00010391794947023660597" iyz="6.2118917254755235858e-08" izz="0.00027164029740908127077" />
</inertial>
</link>

<link name="mx106_block_ankle__list_0bj1pweadmbeeq_default">

<collision>
<origin xyz="2.6020852139652078683e-17 -0.018050000000000059053 0.028500000000009934054" rpy="-3.141592653589793116 3.6923810532281155798e-30 3.141592653589793116" />
<geometry>
<box size="0.040199999999999999623 0.065099999999999991207 0.045999999999999999223" />
</geometry>
</collision>

<collision>
<origin xyz="-0.049400000000020066748 -0.018050000000000065992 0.028500000000009961809" rpy="-9.2644238962482660418e-23 1.570796326794896558 0" />
<geometry>
<box size="0.040199999999999999623 0.065099999999999991207 0.045999999999999999223" />
</geometry>
</collision>
<visual>
<origin xyz="0 0 0" rpy="0 -0 0" />
<geometry>
<mesh filename="mx106_block_ankle__list_0bj1pweadmbeeq_default_visual.stl" />
</geometry>
<material name="mx106_block_ankle__list_0bj1pweadmbeeq_default_material">
<color rgba="0.30196078431372547213 0.30196078431372547213 0.30196078431372547213 1.0" />
</material>
</visual>
<inertial>
<origin xyz="-0.019572401009989255638 -0.015396401985201096582 0.029025166915077664498" rpy="0 0 0" />
<mass value="0.39709667579512258895" />
<inertia ixx="0.0001817888044639689657" ixy="-3.114147575544976449e-05" ixz="-4.1062666594566306371e-06" iyy="0.00037079025525090582608" iyz="-2.080550925575799656e-06" izz="0.0004285801085024416434" />
</inertial>
</link>

<link name="right_foot_">

<collision>
<origin xyz="3.2092384305570931247e-16 -0.036875000000001469103 0.028170000000003178608" rpy="1.5707963267949054398 1.570796326794841713 0" />
<geometry>
<box size="0.052340000000000004576 0.02999999999999999889 0.0062500000000000003469" />
</geometry>
</collision>

<collision>
<origin xyz="-0.043499999999999268419 -0.05349999999999777156 -0.03212999999999829881" rpy="1.5707963267949540676 -7.1539996149285102295e-15 -8.1771603261397814136e-15" />
<geometry>
<cylinder length="0.016000000000000000333" radius="0.0080000000000000001665" />
</geometry>
</collision>

<collision>
<origin xyz="-0.005499999999999791514 -0.041500000000002035261 0.038670000000002889562" rpy="-1.5707963267948399366 -7.9797279894934909169e-15 -8.9151391897941823389e-15" />
<geometry>
<box size="0.091999999999999998446 0.1575999999999999901 0.0030000000000000000625" />
</geometry>
</collision>

<collision>
<origin xyz="0.032500000000000771327 -0.053499999999998382183 -0.03212999999999785472" rpy="1.5707963267949540676 -7.1539996149285102295e-15 -8.1771603261397814136e-15" />
<geometry>
<cylinder length="0.016000000000000000333" radius="0.0080000000000000001665" />
</geometry>
</collision>

<collision>
<origin xyz="-0.043500000000000350886 -0.053500000000005654144 0.10947000000000201014" rpy="-1.5707963267949540676 7.1539996149284928746e-15 3.1415926535897851224" />
<geometry>
<cylinder length="0.016000000000000000333" radius="0.0080000000000000001665" />
</geometry>
</collision>

<collision>
<origin xyz="0.032499999999999605593 -0.053500000000006320278 0.1094700000000025375" rpy="-1.5707963267949540676 7.1539996149284928746e-15 3.1415926535897851224" />
<geometry>
<cylinder length="0.016000000000000000333" radius="0.0080000000000000001665" />
</geometry>
</collision>
<visual>
<origin xyz="0 0 0" rpy="0 -0 0" />
<geometry>
<mesh filename="right_foot__visual.stl" />
</geometry>
<material name="right_foot__material">
<color rgba="0.30196078431372541662 0.3009348111554257521 0.29854087378606020131 1.0" />
</material>
</visual>
<inertial>
<origin xyz="-0.0045443948701719416583 -0.036554210534015411926 0.046646141434125543146" rpy="0 0 0" />
<mass value="0.2818558249669808613" />
<inertia ixx="0.00071822426056174313441" ixy="-2.5093325733320646032e-06" ixz="4.6417350201812976015e-06" iyy="0.00092244498505176370211" iyz="-1.4353691871003647481e-05" izz="0.00026531271855985042547" />
</inertial>
</link>

<link name="right_foot">
<inertial>
<origin xyz="0 0 0" rpy="0 0 0" />
<mass value="1e-9" />
<inertia ixx="0" ixy="0" ixz="0" iyy="0" iyz="0" izz="0" />
</inertial>
</link>
<joint name="right_foot_frame" type="fixed">
<origin xyz="-0.0029999999999994059197 -0.061500000000001553424 0.03617000000000183263" rpy="-1.5707963267949054398 -1.5707963267948401587 0" />
<parent link="right_foot_" />
<child link="right_foot" />
<axis xyz="0 0 0" />
</joint>

<link name="right_ps_0">
<inertial>
<origin xyz="0 0 0" rpy="0 0 0" />
<mass value="1e-9" />
<inertia ixx="0" ixy="0" ixz="0" iyy="0" iyz="0" izz="0" />
</inertial>
</link>
<joint name="right_ps_0_frame" type="fixed">
<origin xyz="-0.043500000000000392519 -0.061500000000005605738 0.10947000000000157993" rpy="-1.5707963267949072161 -1.5707963267948401587 0" />
<parent link="right_foot_" />
<child link="right_ps_0" />
<axis xyz="0 0 0" />
</joint>

<link name="right_ps_1">
<inertial>
<origin xyz="0 0 0" rpy="0 0 0" />
<mass value="1e-9" />
<inertia ixx="0" ixy="0" ixz="0" iyy="0" iyz="0" izz="0" />
</inertial>
</link>
<joint name="right_ps_1_frame" type="fixed">
<origin xyz="-0.04349999999999932393 -0.061499999999997778666 -0.032129999999998770654" rpy="-1.5707963267949056618 -1.5707963267948399366 0" />
<parent link="right_foot_" />
<child link="right_ps_1" />
<axis xyz="0 0 0" />
</joint>

<link name="right_ps_2">
<inertial>
<origin xyz="0 0 0" rpy="0 0 0" />
<mass value="1e-9" />
<inertia ixx="0" ixy="0" ixz="0" iyy="0" iyz="0" izz="0" />
</inertial>
</link>
<joint name="right_ps_2_frame" type="fixed">
<origin xyz="0.032500000000000715816 -0.061499999999998333777 -0.03212999999999829881" rpy="-1.5707963267949072161 -1.5707963267948399366 0" />
<parent link="right_foot_" />
<child link="right_ps_2" />
<axis xyz="0 0 0" />
</joint>

<link name="right_ps_3">
<inertial>
<origin xyz="0 0 0" rpy="0 0 0" />
<mass value="1e-9" />
<inertia ixx="0" ixy="0" ixz="0" iyy="0" iyz="0" izz="0" />
</inertial>
</link>
<joint name="right_ps_3_frame" type="fixed">
<origin xyz="0.032499999999999550082 -0.061500000000006327383 0.10947000000000207953" rpy="-1.5707963267949047736 -1.5707963267948401587 0" />
<parent link="right_foot_" />
<child link="right_ps_3" />
<axis xyz="0 0 0" />
</joint>

<joint name="right_ankle_roll" type="revolute">
<origin xyz="-0.023400000000022520841 0 0.028500000000009961809" rpy="-3.141592653589793116 -1.5707963267948803487 0" />
<parent link="mx106_block_ankle__list_0bj1pweadmbeeq_default" />
<child link="right_foot_" />
<axis xyz="0 0 1" />
<limit effort="10" velocity="6" lower="-0.785398163397448279" upper="0.785398163397448279" />
<joint_properties friction="0.0" />
</joint>

<joint name="right_ankle_pitch" type="revolute">
<origin xyz="1.3444106938820254982e-17 0.14000000000000001332 0" rpy="-2.2999513674700879532e-15 -8.9962181524102428909e-31 -2.2983705748767555774e-30" />
<parent link="tibia_2023_2" />
<child link="mx106_block_ankle__list_0bj1pweadmbeeq_default" />
<axis xyz="0 0 1" />
<limit effort="10" velocity="6" lower="-1.570796326794896558" upper="1.570796326794896558" />
<joint_properties friction="0.0" />
</joint>

<joint name="right_knee" type="revolute">
<origin xyz="4.8919202022545960062e-16 -0.14000000000002205125 0.00099999999998869049112" rpy="1.6827403746079293233e-14 7.0499162063697882079e-15 -3.1415926535897873428" />
<parent link="right_knee_2023" />
<child link="tibia_2023_2" />
<axis xyz="0 0 1" />
<limit effort="10" velocity="6" lower="0" upper="3.141592653589793116" />
<joint_properties friction="0.0" />
</joint>

<joint name="right_hip_pitch" type="revolute">
<origin xyz="-0.02950000000000863043 -2.1718737919229624822e-15 0.023400000000011952905" rpy="-7.6577731246432181099e-14 1.5707963267948612529 0" />
<parent link="mx106_block_mir_hip__list_mr67plvazplf9a_hip" />
<child link="right_knee_2023" />
<axis xyz="0 0 1" />
<limit effort="10" velocity="6" lower="-1.570796326794896558" upper="1.570796326794896558" />
<joint_properties friction="0.0" />
</joint>

<joint name="right_hip_roll" type="revolute">
<origin xyz="0.023400000000000007599 -6.9388939039072283776e-17 -0.040000000000000021649" rpy="1.570796326794896558 -4.4157341147604322877e-14 -1.5707963267949638375" />
<parent link="u_block_2023_2" />
<child link="mx106_block_mir_hip__list_mr67plvazplf9a_hip" />
<axis xyz="0 0 1" />
<limit effort="10" velocity="6" lower="-0.61086523819801530344" upper="0.52359877559829881566" />
<joint_properties friction="0.0" />
</joint>

<joint name="right_hip_yaw" type="revolute">
<origin xyz="0.0033892048686646053524 -0.046399852825939162659 -0.021000000000002325834" rpy="4.4413414402485909771e-14 -4.3542599736725639165e-15 -3.1415926535897256144" />
<parent link="torso_2023" />
<child link="u_block_2023_2" />
<axis xyz="0 0 1" />
<limit effort="10" velocity="6" lower="-1.0471975511965976313" upper="1.0471975511965976313" />
<joint_properties friction="0.0" />
</joint>


<material name="torso_2023_material">
<color rgba="0.1989915035131896992 0.20531734779085586418 0.21164319206852200139 1.0" />
</material>
<material name="u_neck_material">
<color rgba="0.30196078431372547213 0.30196078431372547213 0.30196078431372547213 1.0" />
</material>
<material name="head_2023__field_of_view_false_material">
<color rgba="0.32045575682762950098 0.31487383381853989439 0.29812806479127107462 1.0" />
</material>
<material name="u_shoulder_2023_material">
<color rgba="0.30196078431372547213 0.30196078431372547213 0.30196078431372547213 1.0" />
</material>
<material name="left_humerus_material">
<color rgba="0.26470081700903541622 0.26470081700903541622 0.26470081700903541622 1.0" />
</material>
<material name="radius_v2_material">
<color rgba="0.21421337674205656598 0.21421337674205656598 0.21421337674205656598 1.0" />
</material>
<material name="u_shoulder_2023_2_material">
<color rgba="0.30196078431372547213 0.30196078431372547213 0.30196078431372547213 1.0" />
</material>
<material name="right_humerus_material">
<color rgba="0.26470081700903541622 0.26470081700903541622 0.26470081700903541622 1.0" />
</material>
<material name="radius_v2_2_material">
<color rgba="0.21421337674205656598 0.21421337674205656598 0.21421337674205656598 1.0" />
</material>
<material name="u_block_2023_material">
<color rgba="0.30196078431372552764 0.30196078431372552764 0.30196078431372552764 1.0" />
</material>
<material name="mx106_block_hip__list_0bj1pweadmbeeq_hip_material">
<color rgba="0.30196078431372547213 0.30196078431372547213 0.30196078431372547213 1.0" />
</material>
<material name="left_knee_2023_material">
<color rgba="0.30196078431372547213 0.30196078431372547213 0.30196078431372547213 1.0" />
</material>
<material name="tibia_2023_material">
<color rgba="0.30196078431372547213 0.30196078431372547213 0.30196078431372547213 1.0" />
</material>
<material name="mx106_block_mir_ankle_material">
<color rgba="0.30196078431372547213 0.30196078431372547213 0.30196078431372547213 1.0" />
</material>
<material name="left_foot___list_t0v6opd9rekumc_default_material">
<color rgba="0.30196078431372547213 0.30093481115542580762 0.2985408737860601458 1.0" />
</material>
<material name="u_block_2023_2_material">
<color rgba="0.30196078431372552764 0.30196078431372552764 0.30196078431372552764 1.0" />
</material>
<material name="mx106_block_mir_hip__list_mr67plvazplf9a_hip_material">
<color rgba="0.30196078431372547213 0.30196078431372547213 0.30196078431372547213 1.0" />
</material>
<material name="right_knee_2023_material">
<color rgba="0.30196078431372541662 0.30196078431372541662 0.30196078431372541662 1.0" />
</material>
<material name="tibia_2023_2_material">
<color rgba="0.30196078431372547213 0.30196078431372547213 0.30196078431372547213 1.0" />
</material>
<material name="mx106_block_ankle__list_0bj1pweadmbeeq_default_material">
<color rgba="0.30196078431372547213 0.30196078431372547213 0.30196078431372547213 1.0" />
</material>
<material name="right_foot__material">
<color rgba="0.30196078431372541662 0.3009348111554257521 0.29854087378606020131 1.0" />
</material>
</robot>